WARNING:werkzeug: * Debugger is active!
INFO:werkzeug: * Debugger PIN: 368-418-919
INFO:werkzeug:127.0.0.1 - - [17/Apr/2024 15:17:09] "POST /upload HTTP/1.1" 200 -
INFO:werkzeug:127.0.0.1 - - [17/Apr/2024 15:17:09] "OPTIONS /process HTTP/1.1" 200 -
ERROR:root:An error occurred during OCR processing
Traceback (most recent call last):
  File "/home/sandra/Desktop/ocr_application_react/backend/app.py", line 54, in process_image_endpoint
    process_image(image_path, output_folder)
  File "/home/sandra/Desktop/ocr_application_react/backend/ocr_processing.py", line 99, in process_image
    ocr_text = pytesseract.image_to_string(image, config=ocr_config)
  File "/home/sandra/.local/lib/python3.10/site-packages/pytesseract/pytesseract.py", line 423, in image_to_string
    return {
  File "/home/sandra/.local/lib/python3.10/site-packages/pytesseract/pytesseract.py", line 426, in <lambda>
    Output.STRING: lambda: run_and_get_output(*args),
  File "/home/sandra/.local/lib/python3.10/site-packages/pytesseract/pytesseract.py", line 277, in run_and_get_output
    with save(image) as (temp_name, input_filename):
  File "/usr/lib/python3.10/contextlib.py", line 135, in __enter__
    return next(self.gen)
  File "/home/sandra/.local/lib/python3.10/site-packages/pytesseract/pytesseract.py", line 197, in save
    image, extension = prepare(image)
  File "/home/sandra/.local/lib/python3.10/site-packages/pytesseract/pytesseract.py", line 174, in prepare
    raise TypeError('Unsupported image object')
TypeError: Unsupported image object
INFO:werkzeug:127.0.0.1 - - [17/Apr/2024 15:17:09] "[35m[1mPOST /process HTTP/1.1[0m" 500 -
INFO:werkzeug:127.0.0.1 - - [17/Apr/2024 15:18:17] "POST /upload HTTP/1.1" 200 -
INFO:werkzeug:127.0.0.1 - - [17/Apr/2024 15:18:17] "OPTIONS /process HTTP/1.1" 200 -
INFO:werkzeug:127.0.0.1 - - [17/Apr/2024 15:18:30] "POST /process HTTP/1.1" 200 -
INFO:werkzeug:127.0.0.1 - - [17/Apr/2024 15:18:30] "GET /backend/saved_images/erar-0-1_002_0000280_00044_t.jpg HTTP/1.1" 200 -
INFO:werkzeug:127.0.0.1 - - [17/Apr/2024 15:18:30] "GET /backend/saved_images/erar-0-1_002_0000280_00044_t.jpg HTTP/1.1" 200 -
INFO:werkzeug: * Detected change in '/home/sandra/Desktop/ocr_application_react/backend/app.py', reloading
WARNING:werkzeug: * Debugger is active!
INFO:werkzeug: * Debugger PIN: 368-418-919
INFO:werkzeug:[31m[1mWARNING: This is a development server. Do not use it in a production deployment. Use a production WSGI server instead.[0m
 * Running on http://127.0.0.1:5000
INFO:werkzeug:[33mPress CTRL+C to quit[0m
INFO:werkzeug: * Restarting with stat
WARNING:werkzeug: * Debugger is active!
INFO:werkzeug: * Debugger PIN: 810-366-311
INFO:werkzeug:127.0.0.1 - - [18/Apr/2024 09:37:22] "POST /upload HTTP/1.1" 200 -
INFO:werkzeug:127.0.0.1 - - [18/Apr/2024 09:37:22] "OPTIONS /process HTTP/1.1" 200 -
ERROR:root:An error occurred during OCR processing
Traceback (most recent call last):
  File "/home/sandra/Desktop/ocr_application_react/backend/app.py", line 53, in process_image_endpoint
    process_image(image_path, output_folder)
  File "/home/sandra/Desktop/ocr_application_react/backend/ocr_processing.py", line 99, in process_image
    ocr_text = pytesseract.image_to_string(image, config=ocr_config)
  File "/home/sandra/.local/lib/python3.10/site-packages/pytesseract/pytesseract.py", line 423, in image_to_string
    return {
  File "/home/sandra/.local/lib/python3.10/site-packages/pytesseract/pytesseract.py", line 426, in <lambda>
    Output.STRING: lambda: run_and_get_output(*args),
  File "/home/sandra/.local/lib/python3.10/site-packages/pytesseract/pytesseract.py", line 277, in run_and_get_output
    with save(image) as (temp_name, input_filename):
  File "/usr/lib/python3.10/contextlib.py", line 135, in __enter__
    return next(self.gen)
  File "/home/sandra/.local/lib/python3.10/site-packages/pytesseract/pytesseract.py", line 197, in save
    image, extension = prepare(image)
  File "/home/sandra/.local/lib/python3.10/site-packages/pytesseract/pytesseract.py", line 174, in prepare
    raise TypeError('Unsupported image object')
TypeError: Unsupported image object
INFO:werkzeug:127.0.0.1 - - [18/Apr/2024 09:37:22] "[35m[1mPOST /process HTTP/1.1[0m" 500 -
INFO:werkzeug:127.0.0.1 - - [18/Apr/2024 09:38:43] "POST /upload HTTP/1.1" 200 -
INFO:werkzeug:127.0.0.1 - - [18/Apr/2024 09:38:43] "OPTIONS /process HTTP/1.1" 200 -
ERROR:root:An error occurred during OCR processing
Traceback (most recent call last):
  File "/home/sandra/Desktop/ocr_application_react/backend/app.py", line 53, in process_image_endpoint
    process_image(image_path, output_folder)
  File "/home/sandra/Desktop/ocr_application_react/backend/ocr_processing.py", line 99, in process_image
    ocr_text = pytesseract.image_to_string(image, config=ocr_config)
  File "/home/sandra/.local/lib/python3.10/site-packages/pytesseract/pytesseract.py", line 423, in image_to_string
    return {
  File "/home/sandra/.local/lib/python3.10/site-packages/pytesseract/pytesseract.py", line 426, in <lambda>
    Output.STRING: lambda: run_and_get_output(*args),
  File "/home/sandra/.local/lib/python3.10/site-packages/pytesseract/pytesseract.py", line 277, in run_and_get_output
    with save(image) as (temp_name, input_filename):
  File "/usr/lib/python3.10/contextlib.py", line 135, in __enter__
    return next(self.gen)
  File "/home/sandra/.local/lib/python3.10/site-packages/pytesseract/pytesseract.py", line 197, in save
    image, extension = prepare(image)
  File "/home/sandra/.local/lib/python3.10/site-packages/pytesseract/pytesseract.py", line 174, in prepare
    raise TypeError('Unsupported image object')
TypeError: Unsupported image object
INFO:werkzeug:127.0.0.1 - - [18/Apr/2024 09:38:43] "[35m[1mPOST /process HTTP/1.1[0m" 500 -
INFO:werkzeug:127.0.0.1 - - [18/Apr/2024 09:45:18] "POST /upload HTTP/1.1" 200 -
INFO:werkzeug:127.0.0.1 - - [18/Apr/2024 09:45:19] "OPTIONS /process HTTP/1.1" 200 -
ERROR:root:An error occurred during OCR processing
Traceback (most recent call last):
  File "/home/sandra/Desktop/ocr_application_react/backend/app.py", line 53, in process_image_endpoint
    process_image(image_path, output_folder)
  File "/home/sandra/Desktop/ocr_application_react/backend/ocr_processing.py", line 99, in process_image
    ocr_text = pytesseract.image_to_string(image, config=ocr_config)
  File "/home/sandra/.local/lib/python3.10/site-packages/pytesseract/pytesseract.py", line 423, in image_to_string
    return {
  File "/home/sandra/.local/lib/python3.10/site-packages/pytesseract/pytesseract.py", line 426, in <lambda>
    Output.STRING: lambda: run_and_get_output(*args),
  File "/home/sandra/.local/lib/python3.10/site-packages/pytesseract/pytesseract.py", line 277, in run_and_get_output
    with save(image) as (temp_name, input_filename):
  File "/usr/lib/python3.10/contextlib.py", line 135, in __enter__
    return next(self.gen)
  File "/home/sandra/.local/lib/python3.10/site-packages/pytesseract/pytesseract.py", line 197, in save
    image, extension = prepare(image)
  File "/home/sandra/.local/lib/python3.10/site-packages/pytesseract/pytesseract.py", line 174, in prepare
    raise TypeError('Unsupported image object')
TypeError: Unsupported image object
INFO:werkzeug:127.0.0.1 - - [18/Apr/2024 09:45:19] "[35m[1mPOST /process HTTP/1.1[0m" 500 -
INFO:werkzeug:127.0.0.1 - - [18/Apr/2024 09:54:28] "POST /upload HTTP/1.1" 200 -
INFO:werkzeug:127.0.0.1 - - [18/Apr/2024 09:54:28] "OPTIONS /process HTTP/1.1" 200 -
ERROR:root:An error occurred during OCR processing
Traceback (most recent call last):
  File "/home/sandra/Desktop/ocr_application_react/backend/app.py", line 53, in process_image_endpoint
    process_image(image_path, output_folder)
  File "/home/sandra/Desktop/ocr_application_react/backend/ocr_processing.py", line 99, in process_image
    ocr_text = pytesseract.image_to_string(image, config=ocr_config)
  File "/home/sandra/.local/lib/python3.10/site-packages/pytesseract/pytesseract.py", line 423, in image_to_string
    return {
  File "/home/sandra/.local/lib/python3.10/site-packages/pytesseract/pytesseract.py", line 426, in <lambda>
    Output.STRING: lambda: run_and_get_output(*args),
  File "/home/sandra/.local/lib/python3.10/site-packages/pytesseract/pytesseract.py", line 277, in run_and_get_output
    with save(image) as (temp_name, input_filename):
  File "/usr/lib/python3.10/contextlib.py", line 135, in __enter__
    return next(self.gen)
  File "/home/sandra/.local/lib/python3.10/site-packages/pytesseract/pytesseract.py", line 197, in save
    image, extension = prepare(image)
  File "/home/sandra/.local/lib/python3.10/site-packages/pytesseract/pytesseract.py", line 174, in prepare
    raise TypeError('Unsupported image object')
TypeError: Unsupported image object
INFO:werkzeug:127.0.0.1 - - [18/Apr/2024 09:54:28] "[35m[1mPOST /process HTTP/1.1[0m" 500 -
INFO:werkzeug:127.0.0.1 - - [18/Apr/2024 09:56:56] "POST /upload HTTP/1.1" 200 -
INFO:werkzeug:127.0.0.1 - - [18/Apr/2024 09:56:56] "OPTIONS /process HTTP/1.1" 200 -
ERROR:root:An error occurred during OCR processing
Traceback (most recent call last):
  File "/home/sandra/Desktop/ocr_application_react/backend/app.py", line 53, in process_image_endpoint
    process_image(image_path, output_folder)
  File "/home/sandra/Desktop/ocr_application_react/backend/ocr_processing.py", line 99, in process_image
    ocr_text = pytesseract.image_to_string(image, config=ocr_config)
  File "/home/sandra/.local/lib/python3.10/site-packages/pytesseract/pytesseract.py", line 423, in image_to_string
    return {
  File "/home/sandra/.local/lib/python3.10/site-packages/pytesseract/pytesseract.py", line 426, in <lambda>
    Output.STRING: lambda: run_and_get_output(*args),
  File "/home/sandra/.local/lib/python3.10/site-packages/pytesseract/pytesseract.py", line 277, in run_and_get_output
    with save(image) as (temp_name, input_filename):
  File "/usr/lib/python3.10/contextlib.py", line 135, in __enter__
    return next(self.gen)
  File "/home/sandra/.local/lib/python3.10/site-packages/pytesseract/pytesseract.py", line 197, in save
    image, extension = prepare(image)
  File "/home/sandra/.local/lib/python3.10/site-packages/pytesseract/pytesseract.py", line 174, in prepare
    raise TypeError('Unsupported image object')
TypeError: Unsupported image object
INFO:werkzeug:127.0.0.1 - - [18/Apr/2024 09:56:56] "[35m[1mPOST /process HTTP/1.1[0m" 500 -
INFO:werkzeug: * Detected change in '/home/sandra/Desktop/ocr_application_react/backend/database_connection.py', reloading
INFO:werkzeug: * Restarting with stat
WARNING:werkzeug: * Debugger is active!
INFO:werkzeug: * Debugger PIN: 810-366-311
INFO:werkzeug: * Detected change in '/home/sandra/Desktop/ocr_application_react/backend/ocr_processing.py', reloading
INFO:werkzeug: * Restarting with stat
WARNING:werkzeug: * Debugger is active!
INFO:werkzeug: * Debugger PIN: 810-366-311
INFO:werkzeug:127.0.0.1 - - [18/Apr/2024 10:03:33] "POST /upload HTTP/1.1" 200 -
INFO:werkzeug:127.0.0.1 - - [18/Apr/2024 10:03:33] "OPTIONS /process HTTP/1.1" 200 -
INFO:werkzeug:127.0.0.1 - - [18/Apr/2024 10:03:49] "POST /process HTTP/1.1" 200 -
INFO:werkzeug:127.0.0.1 - - [18/Apr/2024 10:03:49] "GET /backend/saved_images/erar-0-1_002_0000280_00005_t.jpg HTTP/1.1" 200 -
INFO:werkzeug:127.0.0.1 - - [18/Apr/2024 10:04:49] "POST /upload HTTP/1.1" 200 -
INFO:werkzeug:127.0.0.1 - - [18/Apr/2024 10:04:49] "OPTIONS /process HTTP/1.1" 200 -
ERROR:root:An error occurred during OCR processing
Traceback (most recent call last):
  File "/home/sandra/Desktop/ocr_application_react/backend/app.py", line 53, in process_image_endpoint
    process_image(image_path, output_folder)
  File "/home/sandra/Desktop/ocr_application_react/backend/ocr_processing.py", line 83, in process_image
    ocr_text = pytesseract.image_to_string(image, config=ocr_config)
  File "/home/sandra/.local/lib/python3.10/site-packages/pytesseract/pytesseract.py", line 423, in image_to_string
    return {
  File "/home/sandra/.local/lib/python3.10/site-packages/pytesseract/pytesseract.py", line 426, in <lambda>
    Output.STRING: lambda: run_and_get_output(*args),
  File "/home/sandra/.local/lib/python3.10/site-packages/pytesseract/pytesseract.py", line 277, in run_and_get_output
    with save(image) as (temp_name, input_filename):
  File "/usr/lib/python3.10/contextlib.py", line 135, in __enter__
    return next(self.gen)
  File "/home/sandra/.local/lib/python3.10/site-packages/pytesseract/pytesseract.py", line 197, in save
    image, extension = prepare(image)
  File "/home/sandra/.local/lib/python3.10/site-packages/pytesseract/pytesseract.py", line 174, in prepare
    raise TypeError('Unsupported image object')
TypeError: Unsupported image object
INFO:werkzeug:127.0.0.1 - - [18/Apr/2024 10:04:49] "[35m[1mPOST /process HTTP/1.1[0m" 500 -
